<?xml version="1.0" ?>
<!-- =================================================================================== -->
<!-- |    This document was autogenerated by xacro from warehouse_bot_sim.urdf.xacro   | -->
<!-- |    EDITING THIS FILE BY HAND IS NOT RECOMMENDED                                 | -->
<!-- =================================================================================== -->
<robot name="warehouse_bot">
  <gazebo reference="base_link">
    <material>Gazebo/DarkGrey</material>
  </gazebo>
  <!-- Wheel Properties -->
  <!-- TODO: check out fdir1 properties  -->
  <gazebo reference="wheel_left_link">
    <mu1>2000</mu1>
    <mu2>2000</mu2>
    <kp>500000.0</kp>
    <kd>1</kd>
    <minDepth>0.005</minDepth>
    <maxVel>0.1</maxVel>
    <fdir1>1 0 0</fdir1>
    <material>Gazebo/White</material>
  </gazebo>
  <gazebo reference="wheel_right_link">
    <mu1>2000</mu1>
    <mu2>2000</mu2>
    <kp>500000.0</kp>
    <kd>1</kd>
    <minDepth>0.005</minDepth>
    <maxVel>0.1</maxVel>
    <fdir1>1 0 0</fdir1>
    <material>Gazebo/White</material>
  </gazebo>
  <!-- caster wheel properties -->
  <gazebo reference="caster_top_left_link">
    <mu1>0.0</mu1>
    <mu2>0.0</mu2>
    <kp>1000000.0</kp>
    <kd>100.0</kd>
    <minDepth>0.005</minDepth>
    <maxVel>1.0</maxVel>
    <material>Gazebo/FlatBlack</material>
  </gazebo>
  <gazebo reference="caster_top_right_link">
    <mu1>0.0</mu1>
    <mu2>0.0</mu2>
    <kp>1000000.0</kp>
    <kd>100.0</kd>
    <minDepth>0.005</minDepth>
    <maxVel>1.0</maxVel>
    <material>Gazebo/FlatBlack</material>
  </gazebo>
  <gazebo reference="caster_bottom_left_link">
    <mu1>0.0</mu1>
    <mu2>0.0</mu2>
    <kp>1000000.0</kp>
    <kd>100.0</kd>
    <minDepth>0.005</minDepth>
    <maxVel>1.0</maxVel>
    <material>Gazebo/FlatBlack</material>
  </gazebo>
  <gazebo reference="caster_bottom_right_link">
    <mu1>0.0</mu1>
    <mu2>0.0</mu2>
    <kp>1000000.0</kp>
    <kd>100.0</kd>
    <minDepth>0.005</minDepth>
    <maxVel>1.0</maxVel>
    <material>Gazebo/FlatBlack</material>
  </gazebo>
  <!-- simulated lidar -->
  <gazebo reference="base_laser">
    <material>Gazebo/FlatBlack</material>
    <sensor name="lds_lfcd_sensor" type="ray">
      <pose>0 0 0 0 0 0</pose>
      <visualize>false</visualize>
      <update_rate>15</update_rate>
      <ray>
        <scan>
          <horizontal>
            <samples>541</samples>
            <resolution>0.005817</resolution>
            <min_angle>-1.57</min_angle>
            <max_angle>1.57</max_angle>
          </horizontal>
        </scan>
        <range>
          <min>0.05</min>
          <max>25.0</max>
          <resolution>0.0005</resolution>
        </range>
        <noise>
          <type>gaussian</type>
          <mean>0.0</mean>
          <stddev>0.01</stddev>
        </noise>
      </ray>
      <plugin filename="libgazebo_ros_laser.so" name="gazebo_ros_lds_lfcd_controller">
        <topicName>scan</topicName>
        <frameName>base_laser</frameName>
      </plugin>
    </sensor>
  </gazebo>
  <!-- simulated motor controller -->
  <gazebo>
    <plugin filename="libcub_diff_drive.so" name="bot_motor_controller">
      <commandTopic>cmd_vel</commandTopic>
      <odometryTopic>odom</odometryTopic>
      <odometryFrame>odom</odometryFrame>
      <!-- compute odometry from wheels (subject to wheel slippage )-->
      <!-- <odometrySource>encoder</odometrySource> -->
      <!-- compute ideal odometry -->
      <odometrySource>world</odometrySource>
      <publishOdomTF>true</publishOdomTF>
      <robotBaseFrame>base_footprint</robotBaseFrame>
      <publishWheelTF>false</publishWheelTF>
      <publishTf>true</publishTf>
      <publishWheelJointState>true</publishWheelJointState>
      <!-- scale to apply to dtheta of odom computation -->
      <OdomAngularScaleCorrection>1.0</OdomAngularScaleCorrection>
      <legacyMode>false</legacyMode>
      <updateRate>100</updateRate>
      <leftJoint>wheel_left_joint</leftJoint>
      <rightJoint>wheel_right_joint</rightJoint>
      <wheelSeparation>0.319948</wheelSeparation>
      <wheelDiameter>0.197</wheelDiameter>
      <wheelAcceleration>1.5</wheelAcceleration>
      <wheelTorque>10</wheelTorque>
      <rosDebugLevel>na</rosDebugLevel>
    </plugin>
  </gazebo>
  <link name="caster_top_left_link">
    <visual>
      <origin rpy="0 0 0" xyz="0 0 0"/>
      <geometry>
        <sphere radius="0.015"/>
      </geometry>
      <material name="grey">
        <color rgba="0.5 0.5 0.5 1.0"/>
      </material>
    </visual>
    <collision>
      <origin rpy="0 0 0" xyz="0 0 0"/>
      <geometry>
        <sphere radius="0.015"/>
      </geometry>
    </collision>
    <inertial>
      <origin xyz="0 0 0"/>
      <mass value="0.003"/>
      <inertia ixx="0.001" ixy="0.0" ixz="0.0" iyy="0.001" iyz="0.0" izz="0.001"/>
    </inertial>
  </link>
  <joint name="caster_top_left_joint" type="fixed">
    <parent link="base_link"/>
    <child link="caster_top_left_link"/>
    <origin rpy="0.0 0.0 0.0" xyz="0.16 0.16 -0.035"/>
  </joint>
  <link name="caster_bottom_left_link">
    <visual>
      <origin rpy="0 0 0" xyz="0 0 0"/>
      <geometry>
        <sphere radius="0.015"/>
      </geometry>
      <material name="grey">
        <color rgba="0.5 0.5 0.5 1.0"/>
      </material>
    </visual>
    <collision>
      <origin rpy="0 0 0" xyz="0 0 0"/>
      <geometry>
        <sphere radius="0.015"/>
      </geometry>
    </collision>
    <inertial>
      <origin xyz="0 0 0"/>
      <mass value="0.003"/>
      <inertia ixx="0.001" ixy="0.0" ixz="0.0" iyy="0.001" iyz="0.0" izz="0.001"/>
    </inertial>
  </link>
  <joint name="caster_bottom_left_joint" type="fixed">
    <parent link="base_link"/>
    <child link="caster_bottom_left_link"/>
    <origin rpy="0.0 0.0 0.0" xyz="-0.16 0.16 -0.035"/>
  </joint>
  <link name="caster_bottom_right_link">
    <visual>
      <origin rpy="0 0 0" xyz="0 0 0"/>
      <geometry>
        <sphere radius="0.015"/>
      </geometry>
      <material name="grey">
        <color rgba="0.5 0.5 0.5 1.0"/>
      </material>
    </visual>
    <collision>
      <origin rpy="0 0 0" xyz="0 0 0"/>
      <geometry>
        <sphere radius="0.015"/>
      </geometry>
    </collision>
    <inertial>
      <origin xyz="0 0 0"/>
      <mass value="0.003"/>
      <inertia ixx="0.001" ixy="0.0" ixz="0.0" iyy="0.001" iyz="0.0" izz="0.001"/>
    </inertial>
  </link>
  <joint name="caster_bottom_right_joint" type="fixed">
    <parent link="base_link"/>
    <child link="caster_bottom_right_link"/>
    <origin rpy="0.0 0.0 0.0" xyz="-0.16 -0.16 -0.035"/>
  </joint>
  <link name="caster_top_right_link">
    <visual>
      <origin rpy="0 0 0" xyz="0 0 0"/>
      <geometry>
        <sphere radius="0.015"/>
      </geometry>
      <material name="grey">
        <color rgba="0.5 0.5 0.5 1.0"/>
      </material>
    </visual>
    <collision>
      <origin rpy="0 0 0" xyz="0 0 0"/>
      <geometry>
        <sphere radius="0.015"/>
      </geometry>
    </collision>
    <inertial>
      <origin xyz="0 0 0"/>
      <mass value="0.003"/>
      <inertia ixx="0.001" ixy="0.0" ixz="0.0" iyy="0.001" iyz="0.0" izz="0.001"/>
    </inertial>
  </link>
  <joint name="caster_top_right_joint" type="fixed">
    <parent link="base_link"/>
    <child link="caster_top_right_link"/>
    <origin rpy="0.0 0.0 0.0" xyz="0.16 -0.16 -0.035"/>
  </joint>
  <link name="base_laser">
    <visual>
      <geometry>
        <mesh filename="package://warehousebot_simulation/meshes/sick_tim_571.stl"/>
      </geometry>
      <!-- the origin tag defines the transform of the model with respect to its own tf frame -->
      <origin rpy="0 0 0" xyz="0 0 0"/>
    </visual>
  </link>
  <link name="wheel_left_link">
    <visual>
      <geometry>
        <mesh filename="package://warehousebot_simulation/meshes/left_wheel.stl" scale="0.01 0.01 0.01"/>
      </geometry>
      <origin rpy="0 0 0" xyz="0 0 0"/>
    </visual>
    <collision name="base_collision">
      <geometry>
        <mesh filename="package://warehousebot_simulation/meshes/left_wheel.stl" scale="0.01 0.01 0.01"/>
      </geometry>
      <origin rpy="0 0 0" xyz="0 0 0"/>
    </collision>
    <inertial>
      <origin xyz="0 0 0"/>
      <mass value="1"/>
      <inertia ixx="0.00282485" ixy="-1.41127e-06" ixz="1.32139e-08" iyy="0.00283002" iyz="2.09836e-07" izz="0.00515906"/>
    </inertial>
  </link>
  <link name="wheel_right_link">
    <visual>
      <geometry>
        <mesh filename="package://warehousebot_simulation/meshes/right_wheel.stl" scale="0.01 0.01 0.01"/>
      </geometry>
      <origin rpy="0 0 0" xyz="0 0 0"/>
    </visual>
    <collision name="base_collision">
      <geometry>
        <mesh filename="package://warehousebot_simulation/meshes/right_wheel.stl" scale="0.01 0.01 0.01"/>
      </geometry>
      <origin rpy="0 0 0" xyz="0 0 0"/>
    </collision>
    <inertial>
      <origin xyz="0 0 0"/>
      <mass value="1"/>
      <inertia ixx="0.00282485" ixy="-1.41127e-06" ixz="1.32139e-08" iyy="0.00283002" iyz="2.09836e-07" izz="0.00515906"/>
    </inertial>
  </link>
  <link name="base_footprint"/>
  <link name="base_link">
    <visual>
      <geometry>
        <mesh filename="package://warehousebot_simulation/meshes/bot_chassis.stl" scale="0.01 0.01 0.01"/>
      </geometry>
      <material name="Cyan">
        <color rgba="0 1.0 1.0 1.0"/>
      </material>
      <origin rpy="0 0 0" xyz="0 0 0"/>
    </visual>
    <collision name="base_collision">
      <geometry>
        <mesh filename="package://warehousebot_simulation/meshes/bot_chassis.stl" scale="0.01 0.01 0.01"/>
      </geometry>
      <origin rpy="0 0 0" xyz="0 0 0"/>
    </collision>
    <inertial>
      <mass value="550"/>
      <origin rpy="0 0 0" xyz="0 0 0 "/>
      <inertia ixx="220" ixy="0" ixz="0" iyy="220" iyz="0" izz="220"/>
    </inertial>
  </link>
  <joint name="base_footprint_to_base_link" type="fixed">
    <parent link="base_footprint"/>
    <child link="base_link"/>
    <origin xyz="0.0 0.0 0.05"/>
  </joint>
  `

  
  <joint name="wheel_left_joint" type="continuous">
    <parent link="base_link"/>
    <child link="wheel_left_link"/>
    <origin rpy="1.57 0 0" xyz="0 0.159974 0.0485"/>
    <axis xyz="0 0 1"/>
  </joint>
  <joint name="wheel_right_joint" type="continuous">
    <parent link="base_link"/>
    <child link="wheel_right_link"/>
    <origin rpy="1.57 0 0" xyz="0 -0.159974 0.0485"/>
    <axis xyz="0 0 1"/>
  </joint>
  <joint name="base_link_to_laser_front" type="continuous">
    <parent link="base_link"/>
    <child link="base_laser"/>
    <origin rpy="3.142 0.0 0.0" xyz="0.169 0.0 0.035856"/>
  </joint>
</robot>
