<sdf version='1.7'>
  <model name='warehouse_bot'>
    <link name='base_footprint'>
      <inertial>
        <pose>2.5e-05 -0 0.049984 0 -0 0</pose>
        <mass>20.015</mass>
        <inertia>
          <ixx>0.325326</ixx>
          <ixy>-1.3732e-24</ixy>
          <ixz>-1.81869e-05</ixz>
          <iyy>0.325411</iyy>
          <iyz>8.46214e-25</iyz>
          <izz>0.3257</izz>
        </inertia>
      </inertial>
      <collision name='base_footprint_fixed_joint_lump__base_collision_collision'>
        <pose>0 0 0.05 0 -0 0</pose>
        <geometry>
          <mesh>
            <scale>0.01 0.01 0.01</scale>
            <uri>model://warehousebot_simulation/meshes/bot_chassis.stl</uri>
          </mesh>
        </geometry>
      </collision>
      <collision name='base_footprint_fixed_joint_lump__caster_bottom_left_link_collision_1'>
        <pose>-0.16 0.16 0.015 0 -0 0</pose>
        <geometry>
          <sphere>
            <radius>0.015</radius>
          </sphere>
        </geometry>
        <surface>
          <contact>
            <ode>
              <kp>1e+06</kp>
              <kd>100</kd>
              <max_vel>1</max_vel>
              <min_depth>0.005</min_depth>
            </ode>
          </contact>
          <friction>
            <ode>
              <mu>0</mu>
              <mu2>0</mu2>
            </ode>
          </friction>
        </surface>
      </collision>
      <collision name='base_footprint_fixed_joint_lump__caster_bottom_right_link_collision_2'>
        <pose>-0.16 -0.16 0.015 0 -0 0</pose>
        <geometry>
          <sphere>
            <radius>0.015</radius>
          </sphere>
        </geometry>
        <surface>
          <contact>
            <ode>
              <kp>1e+06</kp>
              <kd>100</kd>
              <max_vel>1</max_vel>
              <min_depth>0.005</min_depth>
            </ode>
          </contact>
          <friction>
            <ode>
              <mu>0</mu>
              <mu2>0</mu2>
            </ode>
          </friction>
        </surface>
      </collision>
      <collision name='base_footprint_fixed_joint_lump__caster_top_left_link_collision_3'>
        <pose>0.16 0.16 0.015 0 -0 0</pose>
        <geometry>
          <sphere>
            <radius>0.015</radius>
          </sphere>
        </geometry>
        <surface>
          <contact>
            <ode>
              <kp>1e+06</kp>
              <kd>100</kd>
              <max_vel>1</max_vel>
              <min_depth>0.005</min_depth>
            </ode>
          </contact>
          <friction>
            <ode>
              <mu>0</mu>
              <mu2>0</mu2>
            </ode>
          </friction>
        </surface>
      </collision>
      <collision name='base_footprint_fixed_joint_lump__caster_top_right_link_collision_4'>
        <pose>0.16 -0.16 0.015 0 -0 0</pose>
        <geometry>
          <sphere>
            <radius>0.015</radius>
          </sphere>
        </geometry>
        <surface>
          <contact>
            <ode>
              <kp>1e+06</kp>
              <kd>100</kd>
              <max_vel>1</max_vel>
              <min_depth>0.005</min_depth>
            </ode>
          </contact>
          <friction>
            <ode>
              <mu>0</mu>
              <mu2>0</mu2>
            </ode>
          </friction>
        </surface>
      </collision>
      <visual name='base_footprint_fixed_joint_lump__base_link_visual'>
        <pose>0 0 0.05 0 -0 0</pose>
        <geometry>
          <mesh>
            <scale>0.01 0.01 0.01</scale>
            <uri>model://warehousebot_simulation/meshes/bot_chassis.stl</uri>
          </mesh>
        </geometry>
        <material>
          <script>
            <name>Gazebo/DarkGrey</name>
            <uri>file://media/materials/scripts/gazebo.material</uri>
          </script>
        </material>
      </visual>
      <visual name='base_footprint_fixed_joint_lump__base_laser_visual_1'>
        <pose>0.169 0 0.085856 -3.14119 0 0</pose>
        <geometry>
          <mesh>
            <scale>1 1 1</scale>
            <uri>model://warehousebot_simulation/meshes/sick_tim_571.stl</uri>
          </mesh>
        </geometry>
        <material>
          <script>
            <name>Gazebo/FlatBlack</name>
            <uri>file://media/materials/scripts/gazebo.material</uri>
          </script>
        </material>
      </visual>
      <visual name='base_footprint_fixed_joint_lump__caster_bottom_left_link_visual_2'>
        <pose>-0.16 0.16 0.015 0 -0 0</pose>
        <geometry>
          <sphere>
            <radius>0.015</radius>
          </sphere>
        </geometry>
        <material>
          <script>
            <name>Gazebo/FlatBlack</name>
            <uri>file://media/materials/scripts/gazebo.material</uri>
          </script>
        </material>
      </visual>
      <visual name='base_footprint_fixed_joint_lump__caster_bottom_right_link_visual_3'>
        <pose>-0.16 -0.16 0.015 0 -0 0</pose>
        <geometry>
          <sphere>
            <radius>0.015</radius>
          </sphere>
        </geometry>
        <material>
          <script>
            <name>Gazebo/FlatBlack</name>
            <uri>file://media/materials/scripts/gazebo.material</uri>
          </script>
        </material>
      </visual>
      <visual name='base_footprint_fixed_joint_lump__caster_top_left_link_visual_4'>
        <pose>0.16 0.16 0.015 0 -0 0</pose>
        <geometry>
          <sphere>
            <radius>0.015</radius>
          </sphere>
        </geometry>
        <material>
          <script>
            <name>Gazebo/FlatBlack</name>
            <uri>file://media/materials/scripts/gazebo.material</uri>
          </script>
        </material>
      </visual>
      <visual name='base_footprint_fixed_joint_lump__caster_top_right_link_visual_5'>
        <pose>0.16 -0.16 0.015 0 -0 0</pose>
        <geometry>
          <sphere>
            <radius>0.015</radius>
          </sphere>
        </geometry>
        <material>
          <script>
            <name>Gazebo/FlatBlack</name>
            <uri>file://media/materials/scripts/gazebo.material</uri>
          </script>
        </material>
      </visual>
      <sensor name='hls_lfcd_lds' type='ray'>
        <always_on>1</always_on>
        <visualize>1</visualize>
        <update_rate>15</update_rate>
        <ray>
          <scan>
            <horizontal>
              <samples>541</samples>
              <resolution>0.005817</resolution>
              <min_angle>-1.57</min_angle>
              <max_angle>1.57</max_angle>
            </horizontal>
          </scan>
          <range>
            <min>0.01</min>
            <max>25</max>
            <resolution>0.005</resolution>
          </range>
          <noise>
            <type>gaussian</type>
            <mean>0</mean>
            <stddev>0.01</stddev>
          </noise>
        </ray>
        <plugin name='bot_laserscan' filename='libgazebo_ros_ray_sensor.so'>
          <ros>
            <remapping>~/out:=scan</remapping>
          </ros>
          <output_type>sensor_msgs/LaserScan</output_type>
          <frame_name>base_laser</frame_name>
        </plugin>
        <pose>0.169 0 0.085856 -3.14119 -0 0</pose>
      </sensor>
    </link>
    <joint name='wheel_left_joint' type='revolute'>
      <pose relative_to='base_footprint'>0 0.159974 0.0985 1.57 -0 0</pose>
      <parent>base_footprint</parent>
      <child>wheel_left_link</child>
      <axis>
        <xyz>0 0 1</xyz>
        <limit>
          <lower>-1e+16</lower>
          <upper>1e+16</upper>
        </limit>
        <dynamics>
          <spring_reference>0</spring_reference>
          <spring_stiffness>0</spring_stiffness>
        </dynamics>
      </axis>
    </joint>
    <link name='wheel_left_link'>
      <pose relative_to='wheel_left_joint'>0 0 0 0 -0 0</pose>
      <inertial>
        <pose>0 0 0 0 -0 0</pose>
        <mass>1</mass>
        <inertia>
          <ixx>0.00282485</ixx>
          <ixy>-1.41127e-06</ixy>
          <ixz>1.32139e-08</ixz>
          <iyy>0.00283002</iyy>
          <iyz>2.09836e-07</iyz>
          <izz>0.00515906</izz>
        </inertia>
      </inertial>
      <collision name='wheel_left_link_collision'>
        <pose>0 0 0 0 -0 0</pose>
        <geometry>
          <cylinder>
            <length>0.05</length>
            <radius>0.0985</radius>
          </cylinder>
        </geometry>
        <surface>
          <contact>
            <ode>
              <kp>500000</kp>
              <kd>1</kd>
              <max_vel>0.1</max_vel>
              <min_depth>0.005</min_depth>
            </ode>
          </contact>
          <friction>
            <ode>
              <mu>2000</mu>
              <mu2>2000</mu2>
            </ode>
          </friction>
        </surface>
      </collision>
      <visual name='wheel_left_link_visual'>
        <pose>0 0 0 0 -0 0</pose>
        <geometry>
          <mesh>
            <scale>0.01 0.01 0.01</scale>
            <uri>model://warehousebot_simulation/meshes/left_wheel.stl</uri>
          </mesh>
        </geometry>
        <material>
          <script>
            <name>Gazebo/White</name>
            <uri>file://media/materials/scripts/gazebo.material</uri>
          </script>
        </material>
      </visual>
    </link>
    <joint name='wheel_right_joint' type='revolute'>
      <pose relative_to='base_footprint'>0 -0.159974 0.0985 1.57 -0 0</pose>
      <parent>base_footprint</parent>
      <child>wheel_right_link</child>
      <axis>
        <xyz>0 0 1</xyz>
        <limit>
          <lower>-1e+16</lower>
          <upper>1e+16</upper>
        </limit>
        <dynamics>
          <spring_reference>0</spring_reference>
          <spring_stiffness>0</spring_stiffness>
        </dynamics>
      </axis>
    </joint>
    <link name='wheel_right_link'>
      <pose relative_to='wheel_right_joint'>0 0 0 0 -0 0</pose>
      <inertial>
        <pose>0 0 0 0 -0 0</pose>
        <mass>1</mass>
        <inertia>
          <ixx>0.00282485</ixx>
          <ixy>-1.41127e-06</ixy>
          <ixz>1.32139e-08</ixz>
          <iyy>0.00283002</iyy>
          <iyz>2.09836e-07</iyz>
          <izz>0.00515906</izz>
        </inertia>
      </inertial>
      <collision name='wheel_right_link_collision'>
        <pose>0 0 0 0 -0 0</pose>
        <geometry>
          <cylinder>
            <length>0.05</length>
            <radius>0.0985</radius>
          </cylinder>
        </geometry>
        <surface>
          <contact>
            <ode>
              <kp>500000</kp>
              <kd>1</kd>
              <max_vel>0.1</max_vel>
              <min_depth>0.005</min_depth>
            </ode>
          </contact>
          <friction>
            <ode>
              <mu>2000</mu>
              <mu2>2000</mu2>
            </ode>
          </friction>
        </surface>
      </collision>
      <visual name='wheel_right_link_visual'>
        <pose>0 0 0 0 -0 0</pose>
        <geometry>
          <mesh>
            <scale>0.01 0.01 0.01</scale>
            <uri>model://warehousebot_simulation/meshes/right_wheel.stl</uri>
          </mesh>
        </geometry>
        <material>
          <script>
            <name>Gazebo/White</name>
            <uri>file://media/materials/scripts/gazebo.material</uri>
          </script>
        </material>
      </visual>
    </link>
    <plugin name='bot_motor_controller' filename='libgazebo_ros_diff_drive.so'>
      <update_rate>100</update_rate>
      <left_joint>wheel_left_joint</left_joint>
      <right_joint>wheel_right_joint</right_joint>
      <wheel_separation>0.319948</wheel_separation>
      <wheel_diameter>0.197</wheel_diameter>
      <max_wheel_torque>20</max_wheel_torque>
      <max_wheel_acceleration>1.0</max_wheel_acceleration>
      <command_topic>cmd_vel</command_topic>
      <publish_odom>1</publish_odom>
      <publish_odom_tf>1</publish_odom_tf>
      <publish_wheel_tf>0</publish_wheel_tf>
      <odometry_topic>odom</odometry_topic>
      <odometry_frame>odom</odometry_frame>
      <robot_base_frame>base_footprint</robot_base_frame>
    </plugin>
    <static>0</static>
    <plugin name='warehousebot_joint_state' filename='libgazebo_ros_joint_state_publisher.so'>
      <ros>
        <remapping>~/out:=joint_states</remapping>
      </ros>
      <update_rate>100</update_rate>
      <joint_name>wheel_left_joint</joint_name>
      <joint_name>wheel_right_joint</joint_name>
    </plugin>
  </model>
</sdf>
