<?xml version="1.0"?>
<robot name="warehouse_bot"
  xmlns:xacro="http://ros.org/wiki/xacro">

  <link name="base_laser">
    <visual>
      <geometry>
        <mesh filename="package://warehousebot_simulation/meshes/sick_tim_571.stl"/>
      </geometry>
      <!-- the origin tag defines the transform of the model with respect to its own tf frame -->
      <origin rpy="0 0 0" xyz="0 0 0"/>
    </visual>
  </link>


  <link name="wheel_left_link">
    <visual>
      <geometry>
        <mesh filename="package://warehousebot_simulation/meshes/left_wheel.stl" scale="0.01 0.01 0.01"/>
      </geometry>
      <origin rpy="0 0 0" xyz="0 0 0"/>
    </visual>
  </link>

  <link name="wheel_right_link">
    <visual>
      <geometry>
        <mesh filename="package://warehousebot_simulation/meshes/right_wheel.stl" scale="0.01 0.01 0.01"/>
      </geometry>
      <origin rpy="0 0 0" xyz="0 0 0"/>
    </visual>
  </link>


  <link name="base_footprint"/>

  <link name="base_link">
    <visual>
      <geometry>
        <mesh filename="package://warehousebot_simulation/meshes/bot_chassis.stl" scale="0.01 0.01 0.01"/>
      </geometry>
      <material name="Cyan">
        <color rgba="0 1.0 1.0 1.0"/>
      </material>
      <origin rpy="0 0 0" xyz="0 0 0"/>
    </visual>
  </link>



  <joint name="base_footprint_to_base_link" type="fixed">
    <parent link="base_footprint"/>
    <child link="base_link"/>
    <origin xyz="0.0 0.0 0.05"/>
  </joint>`

  <joint name="wheel_left_joint" type="fixed">
    <parent link="base_link"/>
    <child link="wheel_left_link"/>
    <origin xyz="0 0.159974 0.0485" rpy="1.57 0 0"/>
    <axis xyz="0 0 1"/>
  </joint>

  <joint name="wheel_right_joint" type="continuous">
    <parent link="base_link"/>
    <child link="wheel_right_link"/>
    <origin xyz="0 -0.159974 0.0485" rpy="1.57 0 0"/>
    <axis xyz="0 0 1"/>
  </joint>

  <joint name="base_link_to_laser_front" type="continuous">
    <parent link="base_link"/>
    <child link="base_laser"/>
    <origin xyz="0.169 0.0 0.035856" rpy="3.142 0.0 0.0"/>
  </joint>

</robot>