<?xml version="1.0"?>
<robot name="warehouse_bot"
  xmlns:xacro="http://ros.org/wiki/xacro">


  <xacro:include filename="$(find warehousebot_simulation)/urdf/warehouse_bot_sim.gazebo.xacro"/>

  <xacro:macro name="caster" params="name *origin">
    <link name="${name}_link">
      <visual>
        <origin xyz="0 0 0" rpy="0 0 0"/>
        <geometry>
          <sphere radius="0.015"/>
        </geometry>
        <material name="grey">
          <color rgba="0.5 0.5 0.5 1.0"/>
        </material>
      </visual>
      <collision>
        <origin xyz="0 0 0" rpy="0 0 0"/>
        <geometry>
          <sphere radius="0.015"/>
        </geometry>
      </collision>

      <inertial>
        <origin xyz="0 0 0"/>
        <mass value="0.003"/>
        <inertia ixx="0.001" ixy="0.0" ixz="0.0" iyy="0.001" iyz="0.0" izz="0.001"/>
      </inertial>
    </link>

    <joint name="${name}_joint" type="fixed">
      <parent link="base_link"/>
      <child link="${name}_link"/>
      <xacro:insert_block name="origin"/>
    </joint>
  </xacro:macro>


  <xacro:caster name="caster_top_left">
    <origin xyz="0.16 0.16 -0.035" rpy="0.0 0.0 0.0"/>
  </xacro:caster>

  <xacro:caster name="caster_bottom_left">
    <origin xyz="-0.16 0.16 -0.035" rpy="0.0 0.0 0.0"/>
  </xacro:caster>

  <xacro:caster name="caster_bottom_right">
    <origin xyz="-0.16 -0.16 -0.035" rpy="0.0 0.0 0.0"/>
  </xacro:caster>

  <xacro:caster name="caster_top_right">
    <origin xyz="0.16 -0.16 -0.035" rpy="0.0 0.0 0.0"/>
  </xacro:caster>

  <link name="base_laser">
    <visual>
      <geometry>
        <mesh filename="package://warehousebot_simulation/meshes/sick_tim_571.stl"/>
      </geometry>
      <!-- the origin tag defines the transform of the model with respect to its own tf frame -->
      <origin rpy="0 0 0" xyz="0 0 0"/>
    </visual>
  </link>


  <link name="wheel_left_link">
    <visual>
      <geometry>
        <mesh filename="package://warehousebot_simulation/meshes/left_wheel.stl" scale="0.01 0.01 0.01"/>
      </geometry>
      <origin rpy="0 0 0" xyz="0 0 0"/>
    </visual>
    <collision name="base_collision">
      <geometry>
        <mesh filename="package://warehousebot_simulation/meshes/left_wheel.stl" scale="0.01 0.01 0.01"/>
      </geometry>
      <origin rpy="0 0 0" xyz="0 0 0"/>
    </collision>

    <inertial>
      <origin xyz="0 0 0"/>
      <mass value="1"/>
      <inertia ixx="0.00282485" ixy="-1.41127e-06" ixz="1.32139e-08" iyy="0.00283002" iyz="2.09836e-07" izz="0.00515906"/>
    </inertial>
  </link>

  <link name="wheel_right_link">
    <visual>
      <geometry>
        <mesh filename="package://warehousebot_simulation/meshes/right_wheel.stl" scale="0.01 0.01 0.01"/>
      </geometry>
      <origin rpy="0 0 0" xyz="0 0 0"/>
    </visual>

    <collision name="base_collision">
      <geometry>
        <mesh filename="package://warehousebot_simulation/meshes/right_wheel.stl" scale="0.01 0.01 0.01"/>
      </geometry>
      <origin rpy="0 0 0" xyz="0 0 0"/>
    </collision>

    <inertial>
      <origin xyz="0 0 0"/>
      <mass value="1"/>
      <inertia ixx="0.00282485" ixy="-1.41127e-06" ixz="1.32139e-08" iyy="0.00283002" iyz="2.09836e-07" izz="0.00515906"/>
    </inertial>

  </link>


  <link name="base_footprint"/>

  <link name="base_link">
    <visual>
      <geometry>
        <mesh filename="package://warehousebot_simulation/meshes/bot_chassis.stl" scale="0.01 0.01 0.01"/>
      </geometry>
      <material name="Cyan">
        <color rgba="0 1.0 1.0 1.0"/>
      </material>
      <origin rpy="0 0 0" xyz="0 0 0"/>
    </visual>
    <collision name="base_collision">
      <geometry>
        <mesh filename="package://warehousebot_simulation/meshes/bot_chassis.stl" scale="0.01 0.01 0.01"/>
      </geometry>
      <origin rpy="0 0 0" xyz="0 0 0"/>
    </collision>

    <inertial>
      <mass value="550"/>
      <origin rpy="0 0 0" xyz="0 0 0 "/>
      <inertia ixx="220" ixy="0" ixz="0" iyy="220" iyz="0" izz="220"/>
    </inertial>
  </link>

  <joint name="base_footprint_to_base_link" type="fixed">
    <parent link="base_footprint"/>
    <child link="base_link"/>
    <origin xyz="0.0 0.0 0.05"/>
  </joint>`

  <joint name="wheel_left_joint" type="continuous">
    <parent link="base_link"/>
    <child link="wheel_left_link"/>
    <origin xyz="0 0.159974 0.0485" rpy="1.57 0 0"/>
    <axis xyz="0 0 1"/>
  </joint>

  <joint name="wheel_right_joint" type="continuous">
    <parent link="base_link"/>
    <child link="wheel_right_link"/>
    <origin xyz="0 -0.159974 0.0485" rpy="1.57 0 0"/>
    <axis xyz="0 0 1"/>
  </joint>

  <joint name="base_link_to_laser_front" type="continuous">
    <parent link="base_link"/>
    <child link="base_laser"/>
    <origin xyz="0.169 0.0 0.035856" rpy="3.142 0.0 0.0"/>
  </joint>


</robot>